Workbook

Sheet Scoring 2026
B1: Operational Performance Report
B3: Operating Principles
B4: - The Operational Performance ranking is a framework for measuring restaurant performance. - It defines long-term targets across the core pillars: Customers, Restaurant, and Teams. Each metric in the scorecard is assigned a rating from 1 to 5, with thresholds based on synthetic historical performance and portfolio targets.
B10: - Metrics cover the selected month, except team metrics, which cover the full active team regardless of join date.
B12: 2026 Scores
B15: NETWORK SCORECARD
H16: 2026 Targets | I16: Score Bands | N16: Weighting
B17: Category | C17: Theme / Type | D17: Metric | E17: Weight | F17: Source | G17: Owner | H17: Network | I17: 1 | J17: 2 | K17: 3 | L17: 4 | M17: 5
B18: Transaction Growth Drivers (monthly view) | C18: Overall Satisfaction | E18: =SUM(E19:E21) -> 0.26
C19: Google | D19: Google Score | E19: 0.08 | F19: Survey Platform | G19: Emma | H19: 4.35 | I19: <4,05 | J19: >=4,05 | K19: >=4,20 | L19: >=4,35 | M19: >=4,50 | N19: 0.08
C20: CHAMPS | D20: Overall Mystery Shopper Score | E20: 0.12 | F20: Quality Audit Platform | G20: Emma | H20: 0.88 | I20: <78% | J20: >=78% | K20: >=83% | L20: >=88% | M20: >=94% | N20: 0.12
C21: Complaints | D21: Recla/1000 | E21: 0.06 | F21: Service Desk Platform | G21: Emma | H21: 0.1 | I21: >0,18 | J21: >=0,18 | K21: >=0,13 | L21: >=0,10 | M21: >=0,06 | N21: 0.06
C23: Cleanliness | E23: =E24 -> 0.14
C24: Customer Feedback - Cleanliness | D24: Cleanliness Satisfaction | E24: 0.14 | F24: Survey Platform | G24: Emma | H24: 0.68 | I24: <60% | J24: >=60% | K24: >=64% | L24: >=68% | M24: >=72% | N24: 0.14
C26: Qualité | E26: =E27 -> 0.14
C27: Customer Feedback - Taste | D27: Taste Satisfaction | E27: 0.14 | F27: Survey Platform | G27: Emma | H27: 0.69 | I27: <61% | J27: >=61% | K27: >=65% | L27: >=69% | M27: >=73% | N27: 0.14
C29: Service | E29: =E30 -> 0.11
C30: Mystery Shopper - Speed | D30: Score VM |Speed | E30: 0.11 | F30: Quality Audit Platform | G30: Emma | H30: 0.64 | I30: <57% | J30: >=57% | K30: >=61% | L30: >=64% | M30: >=69% | N30: 0.11
B32: Operational Fundamentals Operations (included in quarterly view) | C32: Team Experience | E32: =SUM(E33:E35) -> 0.16
C33: RGM Training | D33: % Director/GEX2 Certification | E33: 0.05 | F33: Training Platform | G33: Daniel | H33: 0.92 | I33: <60% | J33: >=60% | K33: >=80% | L33: >=92% | M33: >=97% | N33: 0.05
C34: AM/RS Training | D34: % Service Management Certification | E34: 0.05 | F34: Training Platform | G34: Daniel | H34: 0.94 | I34: <60% | J34: >=60% | K34: >=82% | L34: >=94% | M34: >=98% | N34: 0.05
C35: STEW Training | D35: % Fundamentals Certification within 14 Days | E35: 0.06 | F35: Training Platform | G35: Daniel | H35: 0.96 | I35: <60% | J35: >=60% | K35: >=85% | L35: >=96% | M35: >=99% | N35: 0.06
C37: ROCC Standards | E37: =E38+E39 -> 0.19
C38: Overall ROCC | D38: Rating Overall ROCCe | E38: 0.09 | F38: Reporting Platform | G38: Olivia | H38: 0.89 | I38: <72% | J38: >=72% | K38: >=82% | L38: >=89% | M38: >=95% | N38: 0.09
C39: Action Plan Compliance | D39: L3 Action Plan completed within 72h | E39: 0.1 | F39: Reporting Platform | G39: Olivia | H39: 0.93 | I39: <75% | J39: >=75% | K39: >=84% | L39: >=93% | M39: >=98% | N39: 0.1

Sheet Restaurant Dashboard
C1: Period
C2: July YTD
C4: Network Average | E4: 2.2307692 | G4: 4.482 | H4: 4 | I4: 84.98 | J4: 2 | K4: 0.084 | L4: 3 | N4: 0.5893 | O4: 1 | Q4: 0.62464809 | R4: 3 | T4: 56.996928 | U4: 1 | W4: 0.869 | X4: 3 | Y4: 0.567 | Z4: 1 | AA4: 0.806 | AB4: 2 | AC4: 2 | AD4: 0.568 | AE4: 1 | AF4: 0.875 | AG4: 3
G5: Overall Satisfaction 25% | N5: Cleanliness 15% | Q5: Taste 15% | T5: Service 10% | W5: Team Experience 15% | AD5: ROCC Standards 20%
A6: Consultant | B6: Franchisee | C6: Restaurant | D6: Rank | E6: Total Score | G6: Overall Google Score | H6: Google Score | I6: CHAMPS Average | J6: CHAMPS Mystery Shopper Score | K6: Complaints per 1,000 | L6: Complaints Score | N6: % Cleanliness Satisfaction | O6: Cleanliness Satisfaction Score | Q6: % Taste Satisfaction | R6: Taste Satisfaction Score | T6: Speed Average | U6: Speed Mystery Shopper Score | W6: % RGM Certified | X6: RGM Certification Score | Y6: % AM/RS Certified | Z6: AM/RS Certification Score | AA6: % STew Certified within 14 Days v2 | AB6: STEW Certification Score (14 Days) v2 | AD6: Satisfactory ROCC Audit % | AE6: Audit at Standard Score v2 | AF6: L3 Action Plan Average | AG6: Action Plan Score
A7: =IF('Restaurant Base (Hidden)'!A67=0,"", 'Restaurant Base (Hidden)'!A67) -> Harper Langford | B7: =IF('Restaurant Base (Hidden)'!B67=0,"", 'Restaurant Base (Hidden)'!B67) -> Meadowgate Hospitality | C7: =IF('Restaurant Base (Hidden)'!C67=0,"", 'Restaurant Base (Hidden)'!C67) -> Eagle Mews | D7: =+IFERROR(RANK(E7,$E$7:$E$3390,),"") -> 1 | E7: =+IFERROR(INDEX('Restaurant Base (Hidden)'!$A$2:$Z$1048576,MATCH($C7,'Restaurant Base (Hidden)'!$C$2:$C$1048576,0),MATCH(E$6,'Restaurant Base (Hidden)'!$A$1:$Z$1,0)),"") -> 4.2 | F7: =+IFERROR(INDEX('Restaurant Base (Hidden)'!$A$2:$Z$1048576,MATCH($C7,'Restaurant Base (Hidden)'!$C$2:$C$1048576,0),MATCH(F$6,'Restaurant Base (Hidden)'!$A$1:$Z$1,0)),"") | G7: =+IFERROR(INDEX('Restaurant Base (Hidden)'!$A$2:$Z$1048576,MATCH($C7,'Restaurant Base (Hidden)'!$C$2:$C$1048576,0),MATCH(G$6,'Restaurant Base (Hidden)'!$A$1:$Z$1,0)),"") -> 4,557 | H7: =+IFERROR(INDEX('Restaurant Base (Hidden)'!$A$2:$Z$1048576,MATCH($C7,'Restaurant Base (Hidden)'!$C$2:$C$1048576,0),MATCH(H$6,'Restaurant Base (Hidden)'!$A$1:$Z$1,0)),"") -> 5 | I7: =+IFERROR(INDEX('Restaurant Base (Hidden)'!$A$2:$Z$1048576,MATCH($C7,'Restaurant Base (Hidden)'!$C$2:$C$1048576,0),MATCH(I$6,'Restaurant Base (Hidden)'!$A$1:$Z$1,0)),"") -> 86,60 % | J7: =+IFERROR(INDEX('Restaurant Base (Hidden)'!$A$2:$Z$1048576,MATCH($C7,'Restaurant Base (Hidden)'!$C$2:$C$1048576,0),MATCH(J$6,'Restaurant Base (Hidden)'!$A$1:$Z$1,0)),"") -> 3 | K7: =+IFERROR(INDEX('Restaurant Base (Hidden)'!$A$2:$Z$1048576,MATCH($C7,'Restaurant Base (Hidden)'!$C$2:$C$1048576,0),MATCH(K$6,'Restaurant Base (Hidden)'!$A$1:$Z$1,0)),"") -> 0,058 | L7: =+IFERROR(INDEX('Restaurant Base (Hidden)'!$A$2:$Z$1048576,MATCH($C7,'Restaurant Base (Hidden)'!$C$2:$C$1048576,0),MATCH(L$6,'Restaurant Base (Hidden)'!$A$1:$Z$1,0)),"") -> 5 | ... AG7: =+IFERROR(INDEX('Restaurant Base (Hidden)'!$A$2:$Z$1048576,MATCH($C7,'Restaurant Base (Hidden)'!$C$2:$C$1048576,0),MATCH(AG$6,'Restaurant Base (Hidden)'!$A$1:$Z$1,0)),"") -> 4
A8: =IF('Restaurant Base (Hidden)'!A43=0,"", 'Restaurant Base (Hidden)'!A43) -> Logan Redford | B8: =IF('Restaurant Base (Hidden)'!B43=0,"", 'Restaurant Base (Hidden)'!B43) -> Bluecrest Food Partners | C8: =IF('Restaurant Base (Hidden)'!C43=0,"", 'Restaurant Base (Hidden)'!C43) -> Redwood Grove | D8: =+IFERROR(RANK(E8,$E$7:$E$3390,),"") -> 2 | E8: =+IFERROR(INDEX('Restaurant Base (Hidden)'!$A$2:$Z$1048576,MATCH($C8,'Restaurant Base (Hidden)'!$C$2:$C$1048576,0),MATCH(E$6,'Restaurant Base (Hidden)'!$A$1:$Z$1,0)),"") -> 4.05 | F8: =+IFERROR(INDEX('Restaurant Base (Hidden)'!$A$2:$Z$1048576,MATCH($C8,'Restaurant Base (Hidden)'!$C$2:$C$1048576,0),MATCH(F$6,'Restaurant Base (Hidden)'!$A$1:$Z$1,0)),"") | G8: =+IFERROR(INDEX('Restaurant Base (Hidden)'!$A$2:$Z$1048576,MATCH($C8,'Restaurant Base (Hidden)'!$C$2:$C$1048576,0),MATCH(G$6,'Restaurant Base (Hidden)'!$A$1:$Z$1,0)),"") -> 4,229 | H8: =+IFERROR(INDEX('Restaurant Base (Hidden)'!$A$2:$Z$1048576,MATCH($C8,'Restaurant Base (Hidden)'!$C$2:$C$1048576,0),MATCH(H$6,'Restaurant Base (Hidden)'!$A$1:$Z$1,0)),"") -> 3 | I8: =+IFERROR(INDEX('Restaurant Base (Hidden)'!$A$2:$Z$1048576,MATCH($C8,'Restaurant Base (Hidden)'!$C$2:$C$1048576,0),MATCH(I$6,'Restaurant Base (Hidden)'!$A$1:$Z$1,0)),"") -> 96,30 % | J8: =+IFERROR(INDEX('Restaurant Base (Hidden)'!$A$2:$Z$1048576,MATCH($C8,'Restaurant Base (Hidden)'!$C$2:$C$1048576,0),MATCH(J$6,'Restaurant Base (Hidden)'!$A$1:$Z$1,0)),"") -> 5 | K8: =+IFERROR(INDEX('Restaurant Base (Hidden)'!$A$2:$Z$1048576,MATCH($C8,'Restaurant Base (Hidden)'!$C$2:$C$1048576,0),MATCH(K$6,'Restaurant Base (Hidden)'!$A$1:$Z$1,0)),"") -> 0,201 | L8: =+IFERROR(INDEX('Restaurant Base (Hidden)'!$A$2:$Z$1048576,MATCH($C8,'Restaurant Base (Hidden)'!$C$2:$C$1048576,0),MATCH(L$6,'Restaurant Base (Hidden)'!$A$1:$Z$1,0)),"") -> 1 | ... AG8: =+IFERROR(INDEX('Restaurant Base (Hidden)'!$A$2:$Z$1048576,MATCH($C8,'Restaurant Base (Hidden)'!$C$2:$C$1048576,0),MATCH(AG$6,'Restaurant Base (Hidden)'!$A$1:$Z$1,0)),"") -> 5
A9: =IF('Restaurant Base (Hidden)'!A123=0,"", 'Restaurant Base (Hidden)'!A123) -> Elliot Hawthorne | B9: =IF('Restaurant Base (Hidden)'!B123=0,"", 'Restaurant Base (Hidden)'!B123) -> Bluecrest Food Partners | C9: =IF('Restaurant Base (Hidden)'!C123=0,"", 'Restaurant Base (Hidden)'!C123) -> Evergreen Crescent | D9: =+IFERROR(RANK(E9,$E$7:$E$3390,),"") -> 3 | E9: =+IFERROR(INDEX('Restaurant Base (Hidden)'!$A$2:$Z$1048576,MATCH($C9,'Restaurant Base (Hidden)'!$C$2:$C$1048576,0),MATCH(E$6,'Restaurant Base (Hidden)'!$A$1:$Z$1,0)),"") -> 4.03 | F9: =+IFERROR(INDEX('Restaurant Base (Hidden)'!$A$2:$Z$1048576,MATCH($C9,'Restaurant Base (Hidden)'!$C$2:$C$1048576,0),MATCH(F$6,'Restaurant Base (Hidden)'!$A$1:$Z$1,0)),"") | G9: =+IFERROR(INDEX('Restaurant Base (Hidden)'!$A$2:$Z$1048576,MATCH($C9,'Restaurant Base (Hidden)'!$C$2:$C$1048576,0),MATCH(G$6,'Restaurant Base (Hidden)'!$A$1:$Z$1,0)),"") -> 4,569 | H9: =+IFERROR(INDEX('Restaurant Base (Hidden)'!$A$2:$Z$1048576,MATCH($C9,'Restaurant Base (Hidden)'!$C$2:$C$1048576,0),MATCH(H$6,'Restaurant Base (Hidden)'!$A$1:$Z$1,0)),"") -> 5 | I9: =+IFERROR(INDEX('Restaurant Base (Hidden)'!$A$2:$Z$1048576,MATCH($C9,'Restaurant Base (Hidden)'!$C$2:$C$1048576,0),MATCH(I$6,'Restaurant Base (Hidden)'!$A$1:$Z$1,0)),"") -> 86,30 % | J9: =+IFERROR(INDEX('Restaurant Base (Hidden)'!$A$2:$Z$1048576,MATCH($C9,'Restaurant Base (Hidden)'!$C$2:$C$1048576,0),MATCH(J$6,'Restaurant Base (Hidden)'!$A$1:$Z$1,0)),"") -> 3 | K9: =+IFERROR(INDEX('Restaurant Base (Hidden)'!$A$2:$Z$1048576,MATCH($C9,'Restaurant Base (Hidden)'!$C$2:$C$1048576,0),MATCH(K$6,'Restaurant Base (Hidden)'!$A$1:$Z$1,0)),"") -> 0,108 | L9: =+IFERROR(INDEX('Restaurant Base (Hidden)'!$A$2:$Z$1048576,MATCH($C9,'Restaurant Base (Hidden)'!$C$2:$C$1048576,0),MATCH(L$6,'Restaurant Base (Hidden)'!$A$1:$Z$1,0)),"") -> 3 | ... AG9: =+IFERROR(INDEX('Restaurant Base (Hidden)'!$A$2:$Z$1048576,MATCH($C9,'Restaurant Base (Hidden)'!$C$2:$C$1048576,0),MATCH(AG$6,'Restaurant Base (Hidden)'!$A$1:$Z$1,0)),"") -> 4
A10: =IF('Restaurant Base (Hidden)'!A183=0,"", 'Restaurant Base (Hidden)'!A183) -> Harper Langford | B10: =IF('Restaurant Base (Hidden)'!B183=0,"", 'Restaurant Base (Hidden)'!B183) -> Goldenridge Hospitality | C10: =IF('Restaurant Base (Hidden)'!C183=0,"", 'Restaurant Base (Hidden)'!C183) -> Hilltop Gardens | D10: =+IFERROR(RANK(E10,$E$7:$E$3390,),"") -> 4 | E10: =+IFERROR(INDEX('Restaurant Base (Hidden)'!$A$2:$Z$1048576,MATCH($C10,'Restaurant Base (Hidden)'!$C$2:$C$1048576,0),MATCH(E$6,'Restaurant Base (Hidden)'!$A$1:$Z$1,0)),"") -> 3.97 | F10: =+IFERROR(INDEX('Restaurant Base (Hidden)'!$A$2:$Z$1048576,MATCH($C10,'Restaurant Base (Hidden)'!$C$2:$C$1048576,0),MATCH(F$6,'Restaurant Base (Hidden)'!$A$1:$Z$1,0)),"") | G10: =+IFERROR(INDEX('Restaurant Base (Hidden)'!$A$2:$Z$1048576,MATCH($C10,'Restaurant Base (Hidden)'!$C$2:$C$1048576,0),MATCH(G$6,'Restaurant Base (Hidden)'!$A$1:$Z$1,0)),"") -> 4,392 | H10: =+IFERROR(INDEX('Restaurant Base (Hidden)'!$A$2:$Z$1048576,MATCH($C10,'Restaurant Base (Hidden)'!$C$2:$C$1048576,0),MATCH(H$6,'Restaurant Base (Hidden)'!$A$1:$Z$1,0)),"") -> 4 | I10: =+IFERROR(INDEX('Restaurant Base (Hidden)'!$A$2:$Z$1048576,MATCH($C10,'Restaurant Base (Hidden)'!$C$2:$C$1048576,0),MATCH(I$6,'Restaurant Base (Hidden)'!$A$1:$Z$1,0)),"") -> 97,30 % | J10: =+IFERROR(INDEX('Restaurant Base (Hidden)'!$A$2:$Z$1048576,MATCH($C10,'Restaurant Base (Hidden)'!$C$2:$C$1048576,0),MATCH(J$6,'Restaurant Base (Hidden)'!$A$1:$Z$1,0)),"") -> 5 | K10: =+IFERROR(INDEX('Restaurant Base (Hidden)'!$A$2:$Z$1048576,MATCH($C10,'Restaurant Base (Hidden)'!$C$2:$C$1048576,0),MATCH(K$6,'Restaurant Base (Hidden)'!$A$1:$Z$1,0)),"") -> 0,177 | L10: =+IFERROR(INDEX('Restaurant Base (Hidden)'!$A$2:$Z$1048576,MATCH($C10,'Restaurant Base (Hidden)'!$C$2:$C$1048576,0),MATCH(L$6,'Restaurant Base (Hidden)'!$A$1:$Z$1,0)),"") -> 2 | ... AG10: =+IFERROR(INDEX('Restaurant Base (Hidden)'!$A$2:$Z$1048576,MATCH($C10,'Restaurant Base (Hidden)'!$C$2:$C$1048576,0),MATCH(AG$6,'Restaurant Base (Hidden)'!$A$1:$Z$1,0)),"") -> 1
A11: =IF('Restaurant Base (Hidden)'!A253=0,"", 'Restaurant Base (Hidden)'!A253) -> Skyler Everhart | B11: =IF('Restaurant Base (Hidden)'!B253=0,"", 'Restaurant Base (Hidden)'!B253) -> Maplewood Hospitality | C11: =IF('Restaurant Base (Hidden)'!C253=0,"", 'Restaurant Base (Hidden)'!C253) -> Lake Pines | D11: =+IFERROR(RANK(E11,$E$7:$E$3390,),"") -> 5 | E11: =+IFERROR(INDEX('Restaurant Base (Hidden)'!$A$2:$Z$1048576,MATCH($C11,'Restaurant Base (Hidden)'!$C$2:$C$1048576,0),MATCH(E$6,'Restaurant Base (Hidden)'!$A$1:$Z$1,0)),"") -> 3.95 | F11: =+IFERROR(INDEX('Restaurant Base (Hidden)'!$A$2:$Z$1048576,MATCH($C11,'Restaurant Base (Hidden)'!$C$2:$C$1048576,0),MATCH(F$6,'Restaurant Base (Hidden)'!$A$1:$Z$1,0)),"") | G11: =+IFERROR(INDEX('Restaurant Base (Hidden)'!$A$2:$Z$1048576,MATCH($C11,'Restaurant Base (Hidden)'!$C$2:$C$1048576,0),MATCH(G$6,'Restaurant Base (Hidden)'!$A$1:$Z$1,0)),"") -> 4,786 | H11: =+IFERROR(INDEX('Restaurant Base (Hidden)'!$A$2:$Z$1048576,MATCH($C11,'Restaurant Base (Hidden)'!$C$2:$C$1048576,0),MATCH(H$6,'Restaurant Base (Hidden)'!$A$1:$Z$1,0)),"") -> 5 | I11: =+IFERROR(INDEX('Restaurant Base (Hidden)'!$A$2:$Z$1048576,MATCH($C11,'Restaurant Base (Hidden)'!$C$2:$C$1048576,0),MATCH(I$6,'Restaurant Base (Hidden)'!$A$1:$Z$1,0)),"") -> 93,30 % | J11: =+IFERROR(INDEX('Restaurant Base (Hidden)'!$A$2:$Z$1048576,MATCH($C11,'Restaurant Base (Hidden)'!$C$2:$C$1048576,0),MATCH(J$6,'Restaurant Base (Hidden)'!$A$1:$Z$1,0)),"") -> 4 | K11: =+IFERROR(INDEX('Restaurant Base (Hidden)'!$A$2:$Z$1048576,MATCH($C11,'Restaurant Base (Hidden)'!$C$2:$C$1048576,0),MATCH(K$6,'Restaurant Base (Hidden)'!$A$1:$Z$1,0)),"") -> 0,050 | L11: =+IFERROR(INDEX('Restaurant Base (Hidden)'!$A$2:$Z$1048576,MATCH($C11,'Restaurant Base (Hidden)'!$C$2:$C$1048576,0),MATCH(L$6,'Restaurant Base (Hidden)'!$A$1:$Z$1,0)),"") -> 5 | ... AG11: =+IFERROR(INDEX('Restaurant Base (Hidden)'!$A$2:$Z$1048576,MATCH($C11,'Restaurant Base (Hidden)'!$C$2:$C$1048576,0),MATCH(AG$6,'Restaurant Base (Hidden)'!$A$1:$Z$1,0)),"") -> 3
A12: =IF('Restaurant Base (Hidden)'!A2=0,"", 'Restaurant Base (Hidden)'!A2) -> Avery Ashford | B12: =IF('Restaurant Base (Hidden)'!B2=0,"", 'Restaurant Base (Hidden)'!B2) -> Northstar Dining Group | C12: =IF('Restaurant Base (Hidden)'!C2=0,"", 'Restaurant Base (Hidden)'!C2) -> Golden Walk | D12: =+IFERROR(RANK(E12,$E$7:$E$3390,),"") -> 6 | E12: =+IFERROR(INDEX('Restaurant Base (Hidden)'!$A$2:$Z$1048576,MATCH($C12,'Restaurant Base (Hidden)'!$C$2:$C$1048576,0),MATCH(E$6,'Restaurant Base (Hidden)'!$A$1:$Z$1,0)),"") -> 3.91 | F12: =+IFERROR(INDEX('Restaurant Base (Hidden)'!$A$2:$Z$1048576,MATCH($C12,'Restaurant Base (Hidden)'!$C$2:$C$1048576,0),MATCH(F$6,'Restaurant Base (Hidden)'!$A$1:$Z$1,0)),"") | G12: =+IFERROR(INDEX('Restaurant Base (Hidden)'!$A$2:$Z$1048576,MATCH($C12,'Restaurant Base (Hidden)'!$C$2:$C$1048576,0),MATCH(G$6,'Restaurant Base (Hidden)'!$A$1:$Z$1,0)),"") -> 4,627 | H12: =+IFERROR(INDEX('Restaurant Base (Hidden)'!$A$2:$Z$1048576,MATCH($C12,'Restaurant Base (Hidden)'!$C$2:$C$1048576,0),MATCH(H$6,'Restaurant Base (Hidden)'!$A$1:$Z$1,0)),"") -> 5 | I12: =+IFERROR(INDEX('Restaurant Base (Hidden)'!$A$2:$Z$1048576,MATCH($C12,'Restaurant Base (Hidden)'!$C$2:$C$1048576,0),MATCH(I$6,'Restaurant Base (Hidden)'!$A$1:$Z$1,0)),"") -> 95,00 % | J12: =+IFERROR(INDEX('Restaurant Base (Hidden)'!$A$2:$Z$1048576,MATCH($C12,'Restaurant Base (Hidden)'!$C$2:$C$1048576,0),MATCH(J$6,'Restaurant Base (Hidden)'!$A$1:$Z$1,0)),"") -> 5 | K12: =+IFERROR(INDEX('Restaurant Base (Hidden)'!$A$2:$Z$1048576,MATCH($C12,'Restaurant Base (Hidden)'!$C$2:$C$1048576,0),MATCH(K$6,'Restaurant Base (Hidden)'!$A$1:$Z$1,0)),"") -> 0,035 | L12: =+IFERROR(INDEX('Restaurant Base (Hidden)'!$A$2:$Z$1048576,MATCH($C12,'Restaurant Base (Hidden)'!$C$2:$C$1048576,0),MATCH(L$6,'Restaurant Base (Hidden)'!$A$1:$Z$1,0)),"") -> 5 | ... AG12: =+IFERROR(INDEX('Restaurant Base (Hidden)'!$A$2:$Z$1048576,MATCH($C12,'Restaurant Base (Hidden)'!$C$2:$C$1048576,0),MATCH(AG$6,'Restaurant Base (Hidden)'!$A$1:$Z$1,0)),"") -> 2
A13: =IF('Restaurant Base (Hidden)'!A379=0,"", 'Restaurant Base (Hidden)'!A379) -> Avery Ashford | B13: =IF('Restaurant Base (Hidden)'!B379=0,"", 'Restaurant Base (Hidden)'!B379) -> Fairmont Food Group | C13: =IF('Restaurant Base (Hidden)'!C379=0,"", 'Restaurant Base (Hidden)'!C379) -> River Gate | D13: =+IFERROR(RANK(E13,$E$7:$E$3390,),"") -> 7 | E13: =+IFERROR(INDEX('Restaurant Base (Hidden)'!$A$2:$Z$1048576,MATCH($C13,'Restaurant Base (Hidden)'!$C$2:$C$1048576,0),MATCH(E$6,'Restaurant Base (Hidden)'!$A$1:$Z$1,0)),"") -> 3.88 | F13: =+IFERROR(INDEX('Restaurant Base (Hidden)'!$A$2:$Z$1048576,MATCH($C13,'Restaurant Base (Hidden)'!$C$2:$C$1048576,0),MATCH(F$6,'Restaurant Base (Hidden)'!$A$1:$Z$1,0)),"") | G13: =+IFERROR(INDEX('Restaurant Base (Hidden)'!$A$2:$Z$1048576,MATCH($C13,'Restaurant Base (Hidden)'!$C$2:$C$1048576,0),MATCH(G$6,'Restaurant Base (Hidden)'!$A$1:$Z$1,0)),"") -> 4,584 | H13: =+IFERROR(INDEX('Restaurant Base (Hidden)'!$A$2:$Z$1048576,MATCH($C13,'Restaurant Base (Hidden)'!$C$2:$C$1048576,0),MATCH(H$6,'Restaurant Base (Hidden)'!$A$1:$Z$1,0)),"") -> 5 | I13: =+IFERROR(INDEX('Restaurant Base (Hidden)'!$A$2:$Z$1048576,MATCH($C13,'Restaurant Base (Hidden)'!$C$2:$C$1048576,0),MATCH(I$6,'Restaurant Base (Hidden)'!$A$1:$Z$1,0)),"") -> 70,80 % | J13: =+IFERROR(INDEX('Restaurant Base (Hidden)'!$A$2:$Z$1048576,MATCH($C13,'Restaurant Base (Hidden)'!$C$2:$C$1048576,0),MATCH(J$6,'Restaurant Base (Hidden)'!$A$1:$Z$1,0)),"") -> 1 | K13: =+IFERROR(INDEX('Restaurant Base (Hidden)'!$A$2:$Z$1048576,MATCH($C13,'Restaurant Base (Hidden)'!$C$2:$C$1048576,0),MATCH(K$6,'Restaurant Base (Hidden)'!$A$1:$Z$1,0)),"") -> 0,041 | L13: =+IFERROR(INDEX('Restaurant Base (Hidden)'!$A$2:$Z$1048576,MATCH($C13,'Restaurant Base (Hidden)'!$C$2:$C$1048576,0),MATCH(L$6,'Restaurant Base (Hidden)'!$A$1:$Z$1,0)),"") -> 5 | ... AG13: =+IFERROR(INDEX('Restaurant Base (Hidden)'!$A$2:$Z$1048576,MATCH($C13,'Restaurant Base (Hidden)'!$C$2:$C$1048576,0),MATCH(AG$6,'Restaurant Base (Hidden)'!$A$1:$Z$1,0)),"") -> 4
A14: =IF('Restaurant Base (Hidden)'!A362=0,"", 'Restaurant Base (Hidden)'!A362) -> Logan Redford | B14: =IF('Restaurant Base (Hidden)'!B362=0,"", 'Restaurant Base (Hidden)'!B362) -> Northstar Dining Group | C14: =IF('Restaurant Base (Hidden)'!C362=0,"", 'Restaurant Base (Hidden)'!C362) -> Liberty Commons | D14: =+IFERROR(RANK(E14,$E$7:$E$3390,),"") -> 8 | E14: =+IFERROR(INDEX('Restaurant Base (Hidden)'!$A$2:$Z$1048576,MATCH($C14,'Restaurant Base (Hidden)'!$C$2:$C$1048576,0),MATCH(E$6,'Restaurant Base (Hidden)'!$A$1:$Z$1,0)),"") -> 3.84 | F14: =+IFERROR(INDEX('Restaurant Base (Hidden)'!$A$2:$Z$1048576,MATCH($C14,'Restaurant Base (Hidden)'!$C$2:$C$1048576,0),MATCH(F$6,'Restaurant Base (Hidden)'!$A$1:$Z$1,0)),"") | G14: =+IFERROR(INDEX('Restaurant Base (Hidden)'!$A$2:$Z$1048576,MATCH($C14,'Restaurant Base (Hidden)'!$C$2:$C$1048576,0),MATCH(G$6,'Restaurant Base (Hidden)'!$A$1:$Z$1,0)),"") -> 4,571 | H14: =+IFERROR(INDEX('Restaurant Base (Hidden)'!$A$2:$Z$1048576,MATCH($C14,'Restaurant Base (Hidden)'!$C$2:$C$1048576,0),MATCH(H$6,'Restaurant Base (Hidden)'!$A$1:$Z$1,0)),"") -> 5 | I14: =+IFERROR(INDEX('Restaurant Base (Hidden)'!$A$2:$Z$1048576,MATCH($C14,'Restaurant Base (Hidden)'!$C$2:$C$1048576,0),MATCH(I$6,'Restaurant Base (Hidden)'!$A$1:$Z$1,0)),"") -> 97,00 % | J14: =+IFERROR(INDEX('Restaurant Base (Hidden)'!$A$2:$Z$1048576,MATCH($C14,'Restaurant Base (Hidden)'!$C$2:$C$1048576,0),MATCH(J$6,'Restaurant Base (Hidden)'!$A$1:$Z$1,0)),"") -> 5 | K14: =+IFERROR(INDEX('Restaurant Base (Hidden)'!$A$2:$Z$1048576,MATCH($C14,'Restaurant Base (Hidden)'!$C$2:$C$1048576,0),MATCH(K$6,'Restaurant Base (Hidden)'!$A$1:$Z$1,0)),"") -> 0,150 | L14: =+IFERROR(INDEX('Restaurant Base (Hidden)'!$A$2:$Z$1048576,MATCH($C14,'Restaurant Base (Hidden)'!$C$2:$C$1048576,0),MATCH(L$6,'Restaurant Base (Hidden)'!$A$1:$Z$1,0)),"") -> 2 | ... AG14: =+IFERROR(INDEX('Restaurant Base (Hidden)'!$A$2:$Z$1048576,MATCH($C14,'Restaurant Base (Hidden)'!$C$2:$C$1048576,0),MATCH(AG$6,'Restaurant Base (Hidden)'!$A$1:$Z$1,0)),"") -> 1
A15: =IF('Restaurant Base (Hidden)'!A72=0,"", 'Restaurant Base (Hidden)'!A72) -> Logan Redford | B15: =IF('Restaurant Base (Hidden)'!B72=0,"", 'Restaurant Base (Hidden)'!B72) -> Oakmont Dining Partners | C15: =IF('Restaurant Base (Hidden)'!C72=0,"", 'Restaurant Base (Hidden)'!C72) -> Eastwood Way | D15: =+IFERROR(RANK(E15,$E$7:$E$3390,),"") -> 9 | E15: =+IFERROR(INDEX('Restaurant Base (Hidden)'!$A$2:$Z$1048576,MATCH($C15,'Restaurant Base (Hidden)'!$C$2:$C$1048576,0),MATCH(E$6,'Restaurant Base (Hidden)'!$A$1:$Z$1,0)),"") -> 3.83 | F15: =+IFERROR(INDEX('Restaurant Base (Hidden)'!$A$2:$Z$1048576,MATCH($C15,'Restaurant Base (Hidden)'!$C$2:$C$1048576,0),MATCH(F$6,'Restaurant Base (Hidden)'!$A$1:$Z$1,0)),"") | G15: =+IFERROR(INDEX('Restaurant Base (Hidden)'!$A$2:$Z$1048576,MATCH($C15,'Restaurant Base (Hidden)'!$C$2:$C$1048576,0),MATCH(G$6,'Restaurant Base (Hidden)'!$A$1:$Z$1,0)),"") -> 4,580 | H15: =+IFERROR(INDEX('Restaurant Base (Hidden)'!$A$2:$Z$1048576,MATCH($C15,'Restaurant Base (Hidden)'!$C$2:$C$1048576,0),MATCH(H$6,'Restaurant Base (Hidden)'!$A$1:$Z$1,0)),"") -> 5 | I15: =+IFERROR(INDEX('Restaurant Base (Hidden)'!$A$2:$Z$1048576,MATCH($C15,'Restaurant Base (Hidden)'!$C$2:$C$1048576,0),MATCH(I$6,'Restaurant Base (Hidden)'!$A$1:$Z$1,0)),"") -> 59,30 % | J15: =+IFERROR(INDEX('Restaurant Base (Hidden)'!$A$2:$Z$1048576,MATCH($C15,'Restaurant Base (Hidden)'!$C$2:$C$1048576,0),MATCH(J$6,'Restaurant Base (Hidden)'!$A$1:$Z$1,0)),"") -> 1 | K15: =+IFERROR(INDEX('Restaurant Base (Hidden)'!$A$2:$Z$1048576,MATCH($C15,'Restaurant Base (Hidden)'!$C$2:$C$1048576,0),MATCH(K$6,'Restaurant Base (Hidden)'!$A$1:$Z$1,0)),"") -> 0,201 | L15: =+IFERROR(INDEX('Restaurant Base (Hidden)'!$A$2:$Z$1048576,MATCH($C15,'Restaurant Base (Hidden)'!$C$2:$C$1048576,0),MATCH(L$6,'Restaurant Base (Hidden)'!$A$1:$Z$1,0)),"") -> 1 | ... AG15: =+IFERROR(INDEX('Restaurant Base (Hidden)'!$A$2:$Z$1048576,MATCH($C15,'Restaurant Base (Hidden)'!$C$2:$C$1048576,0),MATCH(AG$6,'Restaurant Base (Hidden)'!$A$1:$Z$1,0)),"") -> 2
A16: =IF('Restaurant Base (Hidden)'!A341=0,"", 'Restaurant Base (Hidden)'!A341) -> Taylor Hartwell | B16: =IF('Restaurant Base (Hidden)'!B341=0,"", 'Restaurant Base (Hidden)'!B341) -> Parkstone Restaurant Group | C16: =IF('Restaurant Base (Hidden)'!C341=0,"", 'Restaurant Base (Hidden)'!C341) -> Golden Place | D16: =+IFERROR(RANK(E16,$E$7:$E$3390,),"") -> 9 | E16: =+IFERROR(INDEX('Restaurant Base (Hidden)'!$A$2:$Z$1048576,MATCH($C16,'Restaurant Base (Hidden)'!$C$2:$C$1048576,0),MATCH(E$6,'Restaurant Base (Hidden)'!$A$1:$Z$1,0)),"") -> 3.83 | F16: =+IFERROR(INDEX('Restaurant Base (Hidden)'!$A$2:$Z$1048576,MATCH($C16,'Restaurant Base (Hidden)'!$C$2:$C$1048576,0),MATCH(F$6,'Restaurant Base (Hidden)'!$A$1:$Z$1,0)),"") | G16: =+IFERROR(INDEX('Restaurant Base (Hidden)'!$A$2:$Z$1048576,MATCH($C16,'Restaurant Base (Hidden)'!$C$2:$C$1048576,0),MATCH(G$6,'Restaurant Base (Hidden)'!$A$1:$Z$1,0)),"") -> 4,667 | H16: =+IFERROR(INDEX('Restaurant Base (Hidden)'!$A$2:$Z$1048576,MATCH($C16,'Restaurant Base (Hidden)'!$C$2:$C$1048576,0),MATCH(H$6,'Restaurant Base (Hidden)'!$A$1:$Z$1,0)),"") -> 5 | I16: =+IFERROR(INDEX('Restaurant Base (Hidden)'!$A$2:$Z$1048576,MATCH($C16,'Restaurant Base (Hidden)'!$C$2:$C$1048576,0),MATCH(I$6,'Restaurant Base (Hidden)'!$A$1:$Z$1,0)),"") -> 91,10 % | J16: =+IFERROR(INDEX('Restaurant Base (Hidden)'!$A$2:$Z$1048576,MATCH($C16,'Restaurant Base (Hidden)'!$C$2:$C$1048576,0),MATCH(J$6,'Restaurant Base (Hidden)'!$A$1:$Z$1,0)),"") -> 4 | K16: =+IFERROR(INDEX('Restaurant Base (Hidden)'!$A$2:$Z$1048576,MATCH($C16,'Restaurant Base (Hidden)'!$C$2:$C$1048576,0),MATCH(K$6,'Restaurant Base (Hidden)'!$A$1:$Z$1,0)),"") -> 0,053 | L16: =+IFERROR(INDEX('Restaurant Base (Hidden)'!$A$2:$Z$1048576,MATCH($C16,'Restaurant Base (Hidden)'!$C$2:$C$1048576,0),MATCH(L$6,'Restaurant Base (Hidden)'!$A$1:$Z$1,0)),"") -> 5 | ... AG16: =+IFERROR(INDEX('Restaurant Base (Hidden)'!$A$2:$Z$1048576,MATCH($C16,'Restaurant Base (Hidden)'!$C$2:$C$1048576,0),MATCH(AG$6,'Restaurant Base (Hidden)'!$A$1:$Z$1,0)),"") -> 1
A17: =IF('Restaurant Base (Hidden)'!A129=0,"", 'Restaurant Base (Hidden)'!A129) -> Kendall Prescott | B17: =IF('Restaurant Base (Hidden)'!B129=0,"", 'Restaurant Base (Hidden)'!B129) -> Rivermark Food Group | C17: =IF('Restaurant Base (Hidden)'!C129=0,"", 'Restaurant Base (Hidden)'!C129) -> Lunar Park | D17: =+IFERROR(RANK(E17,$E$7:$E$3390,),"") -> 11 | E17: =+IFERROR(INDEX('Restaurant Base (Hidden)'!$A$2:$Z$1048576,MATCH($C17,'Restaurant Base (Hidden)'!$C$2:$C$1048576,0),MATCH(E$6,'Restaurant Base (Hidden)'!$A$1:$Z$1,0)),"") -> 3.82 | F17: =+IFERROR(INDEX('Restaurant Base (Hidden)'!$A$2:$Z$1048576,MATCH($C17,'Restaurant Base (Hidden)'!$C$2:$C$1048576,0),MATCH(F$6,'Restaurant Base (Hidden)'!$A$1:$Z$1,0)),"") | G17: =+IFERROR(INDEX('Restaurant Base (Hidden)'!$A$2:$Z$1048576,MATCH($C17,'Restaurant Base (Hidden)'!$C$2:$C$1048576,0),MATCH(G$6,'Restaurant Base (Hidden)'!$A$1:$Z$1,0)),"") -> 4,764 | H17: =+IFERROR(INDEX('Restaurant Base (Hidden)'!$A$2:$Z$1048576,MATCH($C17,'Restaurant Base (Hidden)'!$C$2:$C$1048576,0),MATCH(H$6,'Restaurant Base (Hidden)'!$A$1:$Z$1,0)),"") -> 5 | I17: =+IFERROR(INDEX('Restaurant Base (Hidden)'!$A$2:$Z$1048576,MATCH($C17,'Restaurant Base (Hidden)'!$C$2:$C$1048576,0),MATCH(I$6,'Restaurant Base (Hidden)'!$A$1:$Z$1,0)),"") -> 96,50 % | J17: =+IFERROR(INDEX('Restaurant Base (Hidden)'!$A$2:$Z$1048576,MATCH($C17,'Restaurant Base (Hidden)'!$C$2:$C$1048576,0),MATCH(J$6,'Restaurant Base (Hidden)'!$A$1:$Z$1,0)),"") -> 5 | K17: =+IFERROR(INDEX('Restaurant Base (Hidden)'!$A$2:$Z$1048576,MATCH($C17,'Restaurant Base (Hidden)'!$C$2:$C$1048576,0),MATCH(K$6,'Restaurant Base (Hidden)'!$A$1:$Z$1,0)),"") -> 0,144 | L17: =+IFERROR(INDEX('Restaurant Base (Hidden)'!$A$2:$Z$1048576,MATCH($C17,'Restaurant Base (Hidden)'!$C$2:$C$1048576,0),MATCH(L$6,'Restaurant Base (Hidden)'!$A$1:$Z$1,0)),"") -> 2 | ... AG17: =+IFERROR(INDEX('Restaurant Base (Hidden)'!$A$2:$Z$1048576,MATCH($C17,'Restaurant Base (Hidden)'!$C$2:$C$1048576,0),MATCH(AG$6,'Restaurant Base (Hidden)'!$A$1:$Z$1,0)),"") -> 1
A18: =IF('Restaurant Base (Hidden)'!A360=0,"", 'Restaurant Base (Hidden)'!A360) -> Jordan Oakley | B18: =IF('Restaurant Base (Hidden)'!B360=0,"", 'Restaurant Base (Hidden)'!B360) -> Elmwood Dining Group | C18: =IF('Restaurant Base (Hidden)'!C360=0,"", 'Restaurant Base (Hidden)'!C360) -> Northern Place | D18: =+IFERROR(RANK(E18,$E$7:$E$3390,),"") -> 11 | E18: =+IFERROR(INDEX('Restaurant Base (Hidden)'!$A$2:$Z$1048576,MATCH($C18,'Restaurant Base (Hidden)'!$C$2:$C$1048576,0),MATCH(E$6,'Restaurant Base (Hidden)'!$A$1:$Z$1,0)),"") -> 3.82 | F18: =+IFERROR(INDEX('Restaurant Base (Hidden)'!$A$2:$Z$1048576,MATCH($C18,'Restaurant Base (Hidden)'!$C$2:$C$1048576,0),MATCH(F$6,'Restaurant Base (Hidden)'!$A$1:$Z$1,0)),"") | G18: =+IFERROR(INDEX('Restaurant Base (Hidden)'!$A$2:$Z$1048576,MATCH($C18,'Restaurant Base (Hidden)'!$C$2:$C$1048576,0),MATCH(G$6,'Restaurant Base (Hidden)'!$A$1:$Z$1,0)),"") -> 4,464 | H18: =+IFERROR(INDEX('Restaurant Base (Hidden)'!$A$2:$Z$1048576,MATCH($C18,'Restaurant Base (Hidden)'!$C$2:$C$1048576,0),MATCH(H$6,'Restaurant Base (Hidden)'!$A$1:$Z$1,0)),"") -> 4 | I18: =+IFERROR(INDEX('Restaurant Base (Hidden)'!$A$2:$Z$1048576,MATCH($C18,'Restaurant Base (Hidden)'!$C$2:$C$1048576,0),MATCH(I$6,'Restaurant Base (Hidden)'!$A$1:$Z$1,0)),"") -> 80,90 % | J18: =+IFERROR(INDEX('Restaurant Base (Hidden)'!$A$2:$Z$1048576,MATCH($C18,'Restaurant Base (Hidden)'!$C$2:$C$1048576,0),MATCH(J$6,'Restaurant Base (Hidden)'!$A$1:$Z$1,0)),"") -> 2 | K18: =+IFERROR(INDEX('Restaurant Base (Hidden)'!$A$2:$Z$1048576,MATCH($C18,'Restaurant Base (Hidden)'!$C$2:$C$1048576,0),MATCH(K$6,'Restaurant Base (Hidden)'!$A$1:$Z$1,0)),"") -> 0,099 | L18: =+IFERROR(INDEX('Restaurant Base (Hidden)'!$A$2:$Z$1048576,MATCH($C18,'Restaurant Base (Hidden)'!$C$2:$C$1048576,0),MATCH(L$6,'Restaurant Base (Hidden)'!$A$1:$Z$1,0)),"") -> 4 | ... AG18: =+IFERROR(INDEX('Restaurant Base (Hidden)'!$A$2:$Z$1048576,MATCH($C18,'Restaurant Base (Hidden)'!$C$2:$C$1048576,0),MATCH(AG$6,'Restaurant Base (Hidden)'!$A$1:$Z$1,0)),"") -> 4
A19: =IF('Restaurant Base (Hidden)'!A162=0,"", 'Restaurant Base (Hidden)'!A162) -> Quinn Westbrook | B19: =IF('Restaurant Base (Hidden)'!B162=0,"", 'Restaurant Base (Hidden)'!B162) -> Northstar Dining Group | C19: =IF('Restaurant Base (Hidden)'!C162=0,"", 'Restaurant Base (Hidden)'!C162) -> Emerald Quay | D19: =+IFERROR(RANK(E19,$E$7:$E$3390,),"") -> 13 | E19: =+IFERROR(INDEX('Restaurant Base (Hidden)'!$A$2:$Z$1048576,MATCH($C19,'Restaurant Base (Hidden)'!$C$2:$C$1048576,0),MATCH(E$6,'Restaurant Base (Hidden)'!$A$1:$Z$1,0)),"") -> 3.81 | F19: =+IFERROR(INDEX('Restaurant Base (Hidden)'!$A$2:$Z$1048576,MATCH($C19,'Restaurant Base (Hidden)'!$C$2:$C$1048576,0),MATCH(F$6,'Restaurant Base (Hidden)'!$A$1:$Z$1,0)),"") | G19: =+IFERROR(INDEX('Restaurant Base (Hidden)'!$A$2:$Z$1048576,MATCH($C19,'Restaurant Base (Hidden)'!$C$2:$C$1048576,0),MATCH(G$6,'Restaurant Base (Hidden)'!$A$1:$Z$1,0)),"") -> 4,020 | H19: =+IFERROR(INDEX('Restaurant Base (Hidden)'!$A$2:$Z$1048576,MATCH($C19,'Restaurant Base (Hidden)'!$C$2:$C$1048576,0),MATCH(H$6,'Restaurant Base (Hidden)'!$A$1:$Z$1,0)),"") -> 1 | I19: =+IFERROR(INDEX('Restaurant Base (Hidden)'!$A$2:$Z$1048576,MATCH($C19,'Restaurant Base (Hidden)'!$C$2:$C$1048576,0),MATCH(I$6,'Restaurant Base (Hidden)'!$A$1:$Z$1,0)),"") -> 99,20 % | J19: =+IFERROR(INDEX('Restaurant Base (Hidden)'!$A$2:$Z$1048576,MATCH($C19,'Restaurant Base (Hidden)'!$C$2:$C$1048576,0),MATCH(J$6,'Restaurant Base (Hidden)'!$A$1:$Z$1,0)),"") -> 5 | K19: =+IFERROR(INDEX('Restaurant Base (Hidden)'!$A$2:$Z$1048576,MATCH($C19,'Restaurant Base (Hidden)'!$C$2:$C$1048576,0),MATCH(K$6,'Restaurant Base (Hidden)'!$A$1:$Z$1,0)),"") -> 0,119 | L19: =+IFERROR(INDEX('Restaurant Base (Hidden)'!$A$2:$Z$1048576,MATCH($C19,'Restaurant Base (Hidden)'!$C$2:$C$1048576,0),MATCH(L$6,'Restaurant Base (Hidden)'!$A$1:$Z$1,0)),"") -> 3 | ... AG19: =+IFERROR(INDEX('Restaurant Base (Hidden)'!$A$2:$Z$1048576,MATCH($C19,'Restaurant Base (Hidden)'!$C$2:$C$1048576,0),MATCH(AG$6,'Restaurant Base (Hidden)'!$A$1:$Z$1,0)),"") -> 3
A20: =IF('Restaurant Base (Hidden)'!A265=0,"", 'Restaurant Base (Hidden)'!A265) -> Casey Briarwood | B20: =IF('Restaurant Base (Hidden)'!B265=0,"", 'Restaurant Base (Hidden)'!B265) -> Lakeshore Food Partners | C20: =IF('Restaurant Base (Hidden)'!C265=0,"", 'Restaurant Base (Hidden)'!C265) -> Meadow Heights | D20: =+IFERROR(RANK(E20,$E$7:$E$3390,),"") -> 14 | E20: =+IFERROR(INDEX('Restaurant Base (Hidden)'!$A$2:$Z$1048576,MATCH($C20,'Restaurant Base (Hidden)'!$C$2:$C$1048576,0),MATCH(E$6,'Restaurant Base (Hidden)'!$A$1:$Z$1,0)),"") -> 3.78 | F20: =+IFERROR(INDEX('Restaurant Base (Hidden)'!$A$2:$Z$1048576,MATCH($C20,'Restaurant Base (Hidden)'!$C$2:$C$1048576,0),MATCH(F$6,'Restaurant Base (Hidden)'!$A$1:$Z$1,0)),"") | G20: =+IFERROR(INDEX('Restaurant Base (Hidden)'!$A$2:$Z$1048576,MATCH($C20,'Restaurant Base (Hidden)'!$C$2:$C$1048576,0),MATCH(G$6,'Restaurant Base (Hidden)'!$A$1:$Z$1,0)),"") -> 4,203 | H20: =+IFERROR(INDEX('Restaurant Base (Hidden)'!$A$2:$Z$1048576,MATCH($C20,'Restaurant Base (Hidden)'!$C$2:$C$1048576,0),MATCH(H$6,'Restaurant Base (Hidden)'!$A$1:$Z$1,0)),"") -> 3 | I20: =+IFERROR(INDEX('Restaurant Base (Hidden)'!$A$2:$Z$1048576,MATCH($C20,'Restaurant Base (Hidden)'!$C$2:$C$1048576,0),MATCH(I$6,'Restaurant Base (Hidden)'!$A$1:$Z$1,0)),"") -> 88,00 % | J20: =+IFERROR(INDEX('Restaurant Base (Hidden)'!$A$2:$Z$1048576,MATCH($C20,'Restaurant Base (Hidden)'!$C$2:$C$1048576,0),MATCH(J$6,'Restaurant Base (Hidden)'!$A$1:$Z$1,0)),"") -> 4 | K20: =+IFERROR(INDEX('Restaurant Base (Hidden)'!$A$2:$Z$1048576,MATCH($C20,'Restaurant Base (Hidden)'!$C$2:$C$1048576,0),MATCH(K$6,'Restaurant Base (Hidden)'!$A$1:$Z$1,0)),"") -> 0,099 | L20: =+IFERROR(INDEX('Restaurant Base (Hidden)'!$A$2:$Z$1048576,MATCH($C20,'Restaurant Base (Hidden)'!$C$2:$C$1048576,0),MATCH(L$6,'Restaurant Base (Hidden)'!$A$1:$Z$1,0)),"") -> 4 | ... AG20: =+IFERROR(INDEX('Restaurant Base (Hidden)'!$A$2:$Z$1048576,MATCH($C20,'Restaurant Base (Hidden)'!$C$2:$C$1048576,0),MATCH(AG$6,'Restaurant Base (Hidden)'!$A$1:$Z$1,0)),"") -> 3
A21: =IF('Restaurant Base (Hidden)'!A269=0,"", 'Restaurant Base (Hidden)'!A269) -> Finley Kensington | B21: =IF('Restaurant Base (Hidden)'!B269=0,"", 'Restaurant Base (Hidden)'!B269) -> Westfield Food Group | C21: =IF('Restaurant Base (Hidden)'!C269=0,"", 'Restaurant Base (Hidden)'!C269) -> Glen Heath | D21: =+IFERROR(RANK(E21,$E$7:$E$3390,),"") -> 14 | E21: =+IFERROR(INDEX('Restaurant Base (Hidden)'!$A$2:$Z$1048576,MATCH($C21,'Restaurant Base (Hidden)'!$C$2:$C$1048576,0),MATCH(E$6,'Restaurant Base (Hidden)'!$A$1:$Z$1,0)),"") -> 3.78 | F21: =+IFERROR(INDEX('Restaurant Base (Hidden)'!$A$2:$Z$1048576,MATCH($C21,'Restaurant Base (Hidden)'!$C$2:$C$1048576,0),MATCH(F$6,'Restaurant Base (Hidden)'!$A$1:$Z$1,0)),"") | G21: =+IFERROR(INDEX('Restaurant Base (Hidden)'!$A$2:$Z$1048576,MATCH($C21,'Restaurant Base (Hidden)'!$C$2:$C$1048576,0),MATCH(G$6,'Restaurant Base (Hidden)'!$A$1:$Z$1,0)),"") -> 4,263 | H21: =+IFERROR(INDEX('Restaurant Base (Hidden)'!$A$2:$Z$1048576,MATCH($C21,'Restaurant Base (Hidden)'!$C$2:$C$1048576,0),MATCH(H$6,'Restaurant Base (Hidden)'!$A$1:$Z$1,0)),"") -> 3 | I21: =+IFERROR(INDEX('Restaurant Base (Hidden)'!$A$2:$Z$1048576,MATCH($C21,'Restaurant Base (Hidden)'!$C$2:$C$1048576,0),MATCH(I$6,'Restaurant Base (Hidden)'!$A$1:$Z$1,0)),"") -> 86,30 % | J21: =+IFERROR(INDEX('Restaurant Base (Hidden)'!$A$2:$Z$1048576,MATCH($C21,'Restaurant Base (Hidden)'!$C$2:$C$1048576,0),MATCH(J$6,'Restaurant Base (Hidden)'!$A$1:$Z$1,0)),"") -> 3 | K21: =+IFERROR(INDEX('Restaurant Base (Hidden)'!$A$2:$Z$1048576,MATCH($C21,'Restaurant Base (Hidden)'!$C$2:$C$1048576,0),MATCH(K$6,'Restaurant Base (Hidden)'!$A$1:$Z$1,0)),"") -> 0,104 | L21: =+IFERROR(INDEX('Restaurant Base (Hidden)'!$A$2:$Z$1048576,MATCH($C21,'Restaurant Base (Hidden)'!$C$2:$C$1048576,0),MATCH(L$6,'Restaurant Base (Hidden)'!$A$1:$Z$1,0)),"") -> 3 | ... AG21: =+IFERROR(INDEX('Restaurant Base (Hidden)'!$A$2:$Z$1048576,MATCH($C21,'Restaurant Base (Hidden)'!$C$2:$C$1048576,0),MATCH(AG$6,'Restaurant Base (Hidden)'!$A$1:$Z$1,0)),"") -> 5
A22: =IF('Restaurant Base (Hidden)'!A311=0,"", 'Restaurant Base (Hidden)'!A311) -> Skyler Everhart | B22: =IF('Restaurant Base (Hidden)'!B311=0,"", 'Restaurant Base (Hidden)'!B311) -> Rosebridge Hospitality | C22: =IF('Restaurant Base (Hidden)'!C311=0,"", 'Restaurant Base (Hidden)'!C311) -> Crown Court | D22: =+IFERROR(RANK(E22,$E$7:$E$3390,),"") -> 14 | E22: =+IFERROR(INDEX('Restaurant Base (Hidden)'!$A$2:$Z$1048576,MATCH($C22,'Restaurant Base (Hidden)'!$C$2:$C$1048576,0),MATCH(E$6,'Restaurant Base (Hidden)'!$A$1:$Z$1,0)),"") -> 3.78 | F22: =+IFERROR(INDEX('Restaurant Base (Hidden)'!$A$2:$Z$1048576,MATCH($C22,'Restaurant Base (Hidden)'!$C$2:$C$1048576,0),MATCH(F$6,'Restaurant Base (Hidden)'!$A$1:$Z$1,0)),"") | G22: =+IFERROR(INDEX('Restaurant Base (Hidden)'!$A$2:$Z$1048576,MATCH($C22,'Restaurant Base (Hidden)'!$C$2:$C$1048576,0),MATCH(G$6,'Restaurant Base (Hidden)'!$A$1:$Z$1,0)),"") -> 4,455 | H22: =+IFERROR(INDEX('Restaurant Base (Hidden)'!$A$2:$Z$1048576,MATCH($C22,'Restaurant Base (Hidden)'!$C$2:$C$1048576,0),MATCH(H$6,'Restaurant Base (Hidden)'!$A$1:$Z$1,0)),"") -> 4 | I22: =+IFERROR(INDEX('Restaurant Base (Hidden)'!$A$2:$Z$1048576,MATCH($C22,'Restaurant Base (Hidden)'!$C$2:$C$1048576,0),MATCH(I$6,'Restaurant Base (Hidden)'!$A$1:$Z$1,0)),"") -> 97,60 % | J22: =+IFERROR(INDEX('Restaurant Base (Hidden)'!$A$2:$Z$1048576,MATCH($C22,'Restaurant Base (Hidden)'!$C$2:$C$1048576,0),MATCH(J$6,'Restaurant Base (Hidden)'!$A$1:$Z$1,0)),"") -> 5 | K22: =+IFERROR(INDEX('Restaurant Base (Hidden)'!$A$2:$Z$1048576,MATCH($C22,'Restaurant Base (Hidden)'!$C$2:$C$1048576,0),MATCH(K$6,'Restaurant Base (Hidden)'!$A$1:$Z$1,0)),"") -> 0,072 | L22: =+IFERROR(INDEX('Restaurant Base (Hidden)'!$A$2:$Z$1048576,MATCH($C22,'Restaurant Base (Hidden)'!$C$2:$C$1048576,0),MATCH(L$6,'Restaurant Base (Hidden)'!$A$1:$Z$1,0)),"") -> 4 | ... AG22: =+IFERROR(INDEX('Restaurant Base (Hidden)'!$A$2:$Z$1048576,MATCH($C22,'Restaurant Base (Hidden)'!$C$2:$C$1048576,0),MATCH(AG$6,'Restaurant Base (Hidden)'!$A$1:$Z$1,0)),"") -> 1
A23: =IF('Restaurant Base (Hidden)'!A136=0,"", 'Restaurant Base (Hidden)'!A136) -> Rowan Kingsley | B23: =IF('Restaurant Base (Hidden)'!B136=0,"", 'Restaurant Base (Hidden)'!B136) -> Redwood Food Partners | C23: =IF('Restaurant Base (Hidden)'!C136=0,"", 'Restaurant Base (Hidden)'!C136) -> River Place | D23: =+IFERROR(RANK(E23,$E$7:$E$3390,),"") -> 17 | E23: =+IFERROR(INDEX('Restaurant Base (Hidden)'!$A$2:$Z$1048576,MATCH($C23,'Restaurant Base (Hidden)'!$C$2:$C$1048576,0),MATCH(E$6,'Restaurant Base (Hidden)'!$A$1:$Z$1,0)),"") -> 3.77 | F23: =+IFERROR(INDEX('Restaurant Base (Hidden)'!$A$2:$Z$1048576,MATCH($C23,'Restaurant Base (Hidden)'!$C$2:$C$1048576,0),MATCH(F$6,'Restaurant Base (Hidden)'!$A$1:$Z$1,0)),"") | G23: =+IFERROR(INDEX('Restaurant Base (Hidden)'!$A$2:$Z$1048576,MATCH($C23,'Restaurant Base (Hidden)'!$C$2:$C$1048576,0),MATCH(G$6,'Restaurant Base (Hidden)'!$A$1:$Z$1,0)),"") -> 4,582 | H23: =+IFERROR(INDEX('Restaurant Base (Hidden)'!$A$2:$Z$1048576,MATCH($C23,'Restaurant Base (Hidden)'!$C$2:$C$1048576,0),MATCH(H$6,'Restaurant Base (Hidden)'!$A$1:$Z$1,0)),"") -> 5 | I23: =+IFERROR(INDEX('Restaurant Base (Hidden)'!$A$2:$Z$1048576,MATCH($C23,'Restaurant Base (Hidden)'!$C$2:$C$1048576,0),MATCH(I$6,'Restaurant Base (Hidden)'!$A$1:$Z$1,0)),"") -> 96,00 % | J23: =+IFERROR(INDEX('Restaurant Base (Hidden)'!$A$2:$Z$1048576,MATCH($C23,'Restaurant Base (Hidden)'!$C$2:$C$1048576,0),MATCH(J$6,'Restaurant Base (Hidden)'!$A$1:$Z$1,0)),"") -> 5 | K23: =+IFERROR(INDEX('Restaurant Base (Hidden)'!$A$2:$Z$1048576,MATCH($C23,'Restaurant Base (Hidden)'!$C$2:$C$1048576,0),MATCH(K$6,'Restaurant Base (Hidden)'!$A$1:$Z$1,0)),"") -> 0,109 | L23: =+IFERROR(INDEX('Restaurant Base (Hidden)'!$A$2:$Z$1048576,MATCH($C23,'Restaurant Base (Hidden)'!$C$2:$C$1048576,0),MATCH(L$6,'Restaurant Base (Hidden)'!$A$1:$Z$1,0)),"") -> 3 | ... AG23: =+IFERROR(INDEX('Restaurant Base (Hidden)'!$A$2:$Z$1048576,MATCH($C23,'Restaurant Base (Hidden)'!$C$2:$C$1048576,0),MATCH(AG$6,'Restaurant Base (Hidden)'!$A$1:$Z$1,0)),"") -> 3
A24: =IF('Restaurant Base (Hidden)'!A226=0,"", 'Restaurant Base (Hidden)'!A226) -> Arden Brookstone | B24: =IF('Restaurant Base (Hidden)'!B226=0,"", 'Restaurant Base (Hidden)'!B226) -> Highland Crest Restaurants | C24: =IF('Restaurant Base (Hidden)'!C226=0,"", 'Restaurant Base (Hidden)'!C226) -> Highland Crescent | D24: =+IFERROR(RANK(E24,$E$7:$E$3390,),"") -> 17 | E24: =+IFERROR(INDEX('Restaurant Base (Hidden)'!$A$2:$Z$1048576,MATCH($C24,'Restaurant Base (Hidden)'!$C$2:$C$1048576,0),MATCH(E$6,'Restaurant Base (Hidden)'!$A$1:$Z$1,0)),"") -> 3.77 | F24: =+IFERROR(INDEX('Restaurant Base (Hidden)'!$A$2:$Z$1048576,MATCH($C24,'Restaurant Base (Hidden)'!$C$2:$C$1048576,0),MATCH(F$6,'Restaurant Base (Hidden)'!$A$1:$Z$1,0)),"") | G24: =+IFERROR(INDEX('Restaurant Base (Hidden)'!$A$2:$Z$1048576,MATCH($C24,'Restaurant Base (Hidden)'!$C$2:$C$1048576,0),MATCH(G$6,'Restaurant Base (Hidden)'!$A$1:$Z$1,0)),"") -> 4,481 | H24: =+IFERROR(INDEX('Restaurant Base (Hidden)'!$A$2:$Z$1048576,MATCH($C24,'Restaurant Base (Hidden)'!$C$2:$C$1048576,0),MATCH(H$6,'Restaurant Base (Hidden)'!$A$1:$Z$1,0)),"") -> 4 | I24: =+IFERROR(INDEX('Restaurant Base (Hidden)'!$A$2:$Z$1048576,MATCH($C24,'Restaurant Base (Hidden)'!$C$2:$C$1048576,0),MATCH(I$6,'Restaurant Base (Hidden)'!$A$1:$Z$1,0)),"") -> 55,70 % | J24: =+IFERROR(INDEX('Restaurant Base (Hidden)'!$A$2:$Z$1048576,MATCH($C24,'Restaurant Base (Hidden)'!$C$2:$C$1048576,0),MATCH(J$6,'Restaurant Base (Hidden)'!$A$1:$Z$1,0)),"") -> 1 | K24: =+IFERROR(INDEX('Restaurant Base (Hidden)'!$A$2:$Z$1048576,MATCH($C24,'Restaurant Base (Hidden)'!$C$2:$C$1048576,0),MATCH(K$6,'Restaurant Base (Hidden)'!$A$1:$Z$1,0)),"") -> 0,068 | L24: =+IFERROR(INDEX('Restaurant Base (Hidden)'!$A$2:$Z$1048576,MATCH($C24,'Restaurant Base (Hidden)'!$C$2:$C$1048576,0),MATCH(L$6,'Restaurant Base (Hidden)'!$A$1:$Z$1,0)),"") -> 4 | ... AG24: =+IFERROR(INDEX('Restaurant Base (Hidden)'!$A$2:$Z$1048576,MATCH($C24,'Restaurant Base (Hidden)'!$C$2:$C$1048576,0),MATCH(AG$6,'Restaurant Base (Hidden)'!$A$1:$Z$1,0)),"") -> 4
A25: =IF('Restaurant Base (Hidden)'!A240=0,"", 'Restaurant Base (Hidden)'!A240) -> Finley Kensington | B25: =IF('Restaurant Base (Hidden)'!B240=0,"", 'Restaurant Base (Hidden)'!B240) -> Elmwood Dining Group | C25: =IF('Restaurant Base (Hidden)'!C240=0,"", 'Restaurant Base (Hidden)'!C240) -> Silverbrook Commons | D25: =+IFERROR(RANK(E25,$E$7:$E$3390,),"") -> 19 | E25: =+IFERROR(INDEX('Restaurant Base (Hidden)'!$A$2:$Z$1048576,MATCH($C25,'Restaurant Base (Hidden)'!$C$2:$C$1048576,0),MATCH(E$6,'Restaurant Base (Hidden)'!$A$1:$Z$1,0)),"") -> 3.75 | F25: =+IFERROR(INDEX('Restaurant Base (Hidden)'!$A$2:$Z$1048576,MATCH($C25,'Restaurant Base (Hidden)'!$C$2:$C$1048576,0),MATCH(F$6,'Restaurant Base (Hidden)'!$A$1:$Z$1,0)),"") | G25: =+IFERROR(INDEX('Restaurant Base (Hidden)'!$A$2:$Z$1048576,MATCH($C25,'Restaurant Base (Hidden)'!$C$2:$C$1048576,0),MATCH(G$6,'Restaurant Base (Hidden)'!$A$1:$Z$1,0)),"") -> 4,360 | H25: =+IFERROR(INDEX('Restaurant Base (Hidden)'!$A$2:$Z$1048576,MATCH($C25,'Restaurant Base (Hidden)'!$C$2:$C$1048576,0),MATCH(H$6,'Restaurant Base (Hidden)'!$A$1:$Z$1,0)),"") -> 4 | I25: =+IFERROR(INDEX('Restaurant Base (Hidden)'!$A$2:$Z$1048576,MATCH($C25,'Restaurant Base (Hidden)'!$C$2:$C$1048576,0),MATCH(I$6,'Restaurant Base (Hidden)'!$A$1:$Z$1,0)),"") -> 94,40 % | J25: =+IFERROR(INDEX('Restaurant Base (Hidden)'!$A$2:$Z$1048576,MATCH($C25,'Restaurant Base (Hidden)'!$C$2:$C$1048576,0),MATCH(J$6,'Restaurant Base (Hidden)'!$A$1:$Z$1,0)),"") -> 5 | K25: =+IFERROR(INDEX('Restaurant Base (Hidden)'!$A$2:$Z$1048576,MATCH($C25,'Restaurant Base (Hidden)'!$C$2:$C$1048576,0),MATCH(K$6,'Restaurant Base (Hidden)'!$A$1:$Z$1,0)),"") -> 0,110 | L25: =+IFERROR(INDEX('Restaurant Base (Hidden)'!$A$2:$Z$1048576,MATCH($C25,'Restaurant Base (Hidden)'!$C$2:$C$1048576,0),MATCH(L$6,'Restaurant Base (Hidden)'!$A$1:$Z$1,0)),"") -> 3 | ... AG25: =+IFERROR(INDEX('Restaurant Base (Hidden)'!$A$2:$Z$1048576,MATCH($C25,'Restaurant Base (Hidden)'!$C$2:$C$1048576,0),MATCH(AG$6,'Restaurant Base (Hidden)'!$A$1:$Z$1,0)),"") -> 5
A26: =IF('Restaurant Base (Hidden)'!A62=0,"", 'Restaurant Base (Hidden)'!A62) -> Casey Briarwood | B26: =IF('Restaurant Base (Hidden)'!B62=0,"", 'Restaurant Base (Hidden)'!B62) -> Eastmere Foods | C26: =IF('Restaurant Base (Hidden)'!C62=0,"", 'Restaurant Base (Hidden)'!C62) -> Hilltop Quay | D26: =+IFERROR(RANK(E26,$E$7:$E$3390,),"") -> 20 | E26: =+IFERROR(INDEX('Restaurant Base (Hidden)'!$A$2:$Z$1048576,MATCH($C26,'Restaurant Base (Hidden)'!$C$2:$C$1048576,0),MATCH(E$6,'Restaurant Base (Hidden)'!$A$1:$Z$1,0)),"") -> 3.74 | F26: =+IFERROR(INDEX('Restaurant Base (Hidden)'!$A$2:$Z$1048576,MATCH($C26,'Restaurant Base (Hidden)'!$C$2:$C$1048576,0),MATCH(F$6,'Restaurant Base (Hidden)'!$A$1:$Z$1,0)),"") | G26: =+IFERROR(INDEX('Restaurant Base (Hidden)'!$A$2:$Z$1048576,MATCH($C26,'Restaurant Base (Hidden)'!$C$2:$C$1048576,0),MATCH(G$6,'Restaurant Base (Hidden)'!$A$1:$Z$1,0)),"") -> 4,574 | H26: =+IFERROR(INDEX('Restaurant Base (Hidden)'!$A$2:$Z$1048576,MATCH($C26,'Restaurant Base (Hidden)'!$C$2:$C$1048576,0),MATCH(H$6,'Restaurant Base (Hidden)'!$A$1:$Z$1,0)),"") -> 5 | I26: =+IFERROR(INDEX('Restaurant Base (Hidden)'!$A$2:$Z$1048576,MATCH($C26,'Restaurant Base (Hidden)'!$C$2:$C$1048576,0),MATCH(I$6,'Restaurant Base (Hidden)'!$A$1:$Z$1,0)),"") -> 93,10 % | J26: =+IFERROR(INDEX('Restaurant Base (Hidden)'!$A$2:$Z$1048576,MATCH($C26,'Restaurant Base (Hidden)'!$C$2:$C$1048576,0),MATCH(J$6,'Restaurant Base (Hidden)'!$A$1:$Z$1,0)),"") -> 4 | K26: =+IFERROR(INDEX('Restaurant Base (Hidden)'!$A$2:$Z$1048576,MATCH($C26,'Restaurant Base (Hidden)'!$C$2:$C$1048576,0),MATCH(K$6,'Restaurant Base (Hidden)'!$A$1:$Z$1,0)),"") -> 0,116 | L26: =+IFERROR(INDEX('Restaurant Base (Hidden)'!$A$2:$Z$1048576,MATCH($C26,'Restaurant Base (Hidden)'!$C$2:$C$1048576,0),MATCH(L$6,'Restaurant Base (Hidden)'!$A$1:$Z$1,0)),"") -> 3 | ... AG26: =+IFERROR(INDEX('Restaurant Base (Hidden)'!$A$2:$Z$1048576,MATCH($C26,'Restaurant Base (Hidden)'!$C$2:$C$1048576,0),MATCH(AG$6,'Restaurant Base (Hidden)'!$A$1:$Z$1,0)),"") -> 3
A27: =IF('Restaurant Base (Hidden)'!A330=0,"", 'Restaurant Base (Hidden)'!A330) -> Jamie Northcott | B27: =IF('Restaurant Base (Hidden)'!B330=0,"", 'Restaurant Base (Hidden)'!B330) -> Evercrest Restaurants | C27: =IF('Restaurant Base (Hidden)'!C330=0,"", 'Restaurant Base (Hidden)'!C330) -> Parkside Grove | D27: =+IFERROR(RANK(E27,$E$7:$E$3390,),"") -> 20 | E27: =+IFERROR(INDEX('Restaurant Base (Hidden)'!$A$2:$Z$1048576,MATCH($C27,'Restaurant Base (Hidden)'!$C$2:$C$1048576,0),MATCH(E$6,'Restaurant Base (Hidden)'!$A$1:$Z$1,0)),"") -> 3.74 | F27: =+IFERROR(INDEX('Restaurant Base (Hidden)'!$A$2:$Z$1048576,MATCH($C27,'Restaurant Base (Hidden)'!$C$2:$C$1048576,0),MATCH(F$6,'Restaurant Base (Hidden)'!$A$1:$Z$1,0)),"") | G27: =+IFERROR(INDEX('Restaurant Base (Hidden)'!$A$2:$Z$1048576,MATCH($C27,'Restaurant Base (Hidden)'!$C$2:$C$1048576,0),MATCH(G$6,'Restaurant Base (Hidden)'!$A$1:$Z$1,0)),"") -> 4,750 | H27: =+IFERROR(INDEX('Restaurant Base (Hidden)'!$A$2:$Z$1048576,MATCH($C27,'Restaurant Base (Hidden)'!$C$2:$C$1048576,0),MATCH(H$6,'Restaurant Base (Hidden)'!$A$1:$Z$1,0)),"") -> 5 | I27: =+IFERROR(INDEX('Restaurant Base (Hidden)'!$A$2:$Z$1048576,MATCH($C27,'Restaurant Base (Hidden)'!$C$2:$C$1048576,0),MATCH(I$6,'Restaurant Base (Hidden)'!$A$1:$Z$1,0)),"") -> 79,70 % | J27: =+IFERROR(INDEX('Restaurant Base (Hidden)'!$A$2:$Z$1048576,MATCH($C27,'Restaurant Base (Hidden)'!$C$2:$C$1048576,0),MATCH(J$6,'Restaurant Base (Hidden)'!$A$1:$Z$1,0)),"") -> 2 | K27: =+IFERROR(INDEX('Restaurant Base (Hidden)'!$A$2:$Z$1048576,MATCH($C27,'Restaurant Base (Hidden)'!$C$2:$C$1048576,0),MATCH(K$6,'Restaurant Base (Hidden)'!$A$1:$Z$1,0)),"") -> 0,047 | L27: =+IFERROR(INDEX('Restaurant Base (Hidden)'!$A$2:$Z$1048576,MATCH($C27,'Restaurant Base (Hidden)'!$C$2:$C$1048576,0),MATCH(L$6,'Restaurant Base (Hidden)'!$A$1:$Z$1,0)),"") -> 5 | ... AG27: =+IFERROR(INDEX('Restaurant Base (Hidden)'!$A$2:$Z$1048576,MATCH($C27,'Restaurant Base (Hidden)'!$C$2:$C$1048576,0),MATCH(AG$6,'Restaurant Base (Hidden)'!$A$1:$Z$1,0)),"") -> 3
A28: =IF('Restaurant Base (Hidden)'!A76=0,"", 'Restaurant Base (Hidden)'!A76) -> Reese Whitmore | B28: =IF('Restaurant Base (Hidden)'!B76=0,"", 'Restaurant Base (Hidden)'!B76) -> Crestwood Dining | C28: =IF('Restaurant Base (Hidden)'!C76=0,"", 'Restaurant Base (Hidden)'!C76) -> Highland Quay | D28: =+IFERROR(RANK(E28,$E$7:$E$3390,),"") -> 22 | E28: =+IFERROR(INDEX('Restaurant Base (Hidden)'!$A$2:$Z$1048576,MATCH($C28,'Restaurant Base (Hidden)'!$C$2:$C$1048576,0),MATCH(E$6,'Restaurant Base (Hidden)'!$A$1:$Z$1,0)),"") -> 3.72 | F28: =+IFERROR(INDEX('Restaurant Base (Hidden)'!$A$2:$Z$1048576,MATCH($C28,'Restaurant Base (Hidden)'!$C$2:$C$1048576,0),MATCH(F$6,'Restaurant Base (Hidden)'!$A$1:$Z$1,0)),"") | G28: =+IFERROR(INDEX('Restaurant Base (Hidden)'!$A$2:$Z$1048576,MATCH($C28,'Restaurant Base (Hidden)'!$C$2:$C$1048576,0),MATCH(G$6,'Restaurant Base (Hidden)'!$A$1:$Z$1,0)),"") -> 4,576 | H28: =+IFERROR(INDEX('Restaurant Base (Hidden)'!$A$2:$Z$1048576,MATCH($C28,'Restaurant Base (Hidden)'!$C$2:$C$1048576,0),MATCH(H$6,'Restaurant Base (Hidden)'!$A$1:$Z$1,0)),"") -> 5 | I28: =+IFERROR(INDEX('Restaurant Base (Hidden)'!$A$2:$Z$1048576,MATCH($C28,'Restaurant Base (Hidden)'!$C$2:$C$1048576,0),MATCH(I$6,'Restaurant Base (Hidden)'!$A$1:$Z$1,0)),"") -> 91,80 % | J28: =+IFERROR(INDEX('Restaurant Base (Hidden)'!$A$2:$Z$1048576,MATCH($C28,'Restaurant Base (Hidden)'!$C$2:$C$1048576,0),MATCH(J$6,'Restaurant Base (Hidden)'!$A$1:$Z$1,0)),"") -> 4 | K28: =+IFERROR(INDEX('Restaurant Base (Hidden)'!$A$2:$Z$1048576,MATCH($C28,'Restaurant Base (Hidden)'!$C$2:$C$1048576,0),MATCH(K$6,'Restaurant Base (Hidden)'!$A$1:$Z$1,0)),"") -> 0,085 | L28: =+IFERROR(INDEX('Restaurant Base (Hidden)'!$A$2:$Z$1048576,MATCH($C28,'Restaurant Base (Hidden)'!$C$2:$C$1048576,0),MATCH(L$6,'Restaurant Base (Hidden)'!$A$1:$Z$1,0)),"") -> 4 | ... AG28: =+IFERROR(INDEX('Restaurant Base (Hidden)'!$A$2:$Z$1048576,MATCH($C28,'Restaurant Base (Hidden)'!$C$2:$C$1048576,0),MATCH(AG$6,'Restaurant Base (Hidden)'!$A$1:$Z$1,0)),"") -> 4
A29: =IF('Restaurant Base (Hidden)'!A80=0,"", 'Restaurant Base (Hidden)'!A80) -> Taylor Hartwell | B29: =IF('Restaurant Base (Hidden)'!B80=0,"", 'Restaurant Base (Hidden)'!B80) -> Elmwood Dining Group | C29: =IF('Restaurant Base (Hidden)'!C80=0,"", 'Restaurant Base (Hidden)'!C80) -> Riverside Gardens | D29: =+IFERROR(RANK(E29,$E$7:$E$3390,),"") -> 22 | E29: =+IFERROR(INDEX('Restaurant Base (Hidden)'!$A$2:$Z$1048576,MATCH($C29,'Restaurant Base (Hidden)'!$C$2:$C$1048576,0),MATCH(E$6,'Restaurant Base (Hidden)'!$A$1:$Z$1,0)),"") -> 3.72 | F29: =+IFERROR(INDEX('Restaurant Base (Hidden)'!$A$2:$Z$1048576,MATCH($C29,'Restaurant Base (Hidden)'!$C$2:$C$1048576,0),MATCH(F$6,'Restaurant Base (Hidden)'!$A$1:$Z$1,0)),"") | G29: =+IFERROR(INDEX('Restaurant Base (Hidden)'!$A$2:$Z$1048576,MATCH($C29,'Restaurant Base (Hidden)'!$C$2:$C$1048576,0),MATCH(G$6,'Restaurant Base (Hidden)'!$A$1:$Z$1,0)),"") -> 4,126 | H29: =+IFERROR(INDEX('Restaurant Base (Hidden)'!$A$2:$Z$1048576,MATCH($C29,'Restaurant Base (Hidden)'!$C$2:$C$1048576,0),MATCH(H$6,'Restaurant Base (Hidden)'!$A$1:$Z$1,0)),"") -> 2 | I29: =+IFERROR(INDEX('Restaurant Base (Hidden)'!$A$2:$Z$1048576,MATCH($C29,'Restaurant Base (Hidden)'!$C$2:$C$1048576,0),MATCH(I$6,'Restaurant Base (Hidden)'!$A$1:$Z$1,0)),"") -> 92,90 % | J29: =+IFERROR(INDEX('Restaurant Base (Hidden)'!$A$2:$Z$1048576,MATCH($C29,'Restaurant Base (Hidden)'!$C$2:$C$1048576,0),MATCH(J$6,'Restaurant Base (Hidden)'!$A$1:$Z$1,0)),"") -> 4 | K29: =+IFERROR(INDEX('Restaurant Base (Hidden)'!$A$2:$Z$1048576,MATCH($C29,'Restaurant Base (Hidden)'!$C$2:$C$1048576,0),MATCH(K$6,'Restaurant Base (Hidden)'!$A$1:$Z$1,0)),"") -> 0,053 | L29: =+IFERROR(INDEX('Restaurant Base (Hidden)'!$A$2:$Z$1048576,MATCH($C29,'Restaurant Base (Hidden)'!$C$2:$C$1048576,0),MATCH(L$6,'Restaurant Base (Hidden)'!$A$1:$Z$1,0)),"") -> 5 | ... AG29: =+IFERROR(INDEX('Restaurant Base (Hidden)'!$A$2:$Z$1048576,MATCH($C29,'Restaurant Base (Hidden)'!$C$2:$C$1048576,0),MATCH(AG$6,'Restaurant Base (Hidden)'!$A$1:$Z$1,0)),"") -> 3
A30: =IF('Restaurant Base (Hidden)'!A171=0,"", 'Restaurant Base (Hidden)'!A171) -> Dakota Cavendish | B30: =IF('Restaurant Base (Hidden)'!B171=0,"", 'Restaurant Base (Hidden)'!B171) -> Harborline Dining | C30: =IF('Restaurant Base (Hidden)'!C171=0,"", 'Restaurant Base (Hidden)'!C171) -> Meadow Place | D30: =+IFERROR(RANK(E30,$E$7:$E$3390,),"") -> 22 | E30: =+IFERROR(INDEX('Restaurant Base (Hidden)'!$A$2:$Z$1048576,MATCH($C30,'Restaurant Base (Hidden)'!$C$2:$C$1048576,0),MATCH(E$6,'Restaurant Base (Hidden)'!$A$1:$Z$1,0)),"") -> 3.72 | F30: =+IFERROR(INDEX('Restaurant Base (Hidden)'!$A$2:$Z$1048576,MATCH($C30,'Restaurant Base (Hidden)'!$C$2:$C$1048576,0),MATCH(F$6,'Restaurant Base (Hidden)'!$A$1:$Z$1,0)),"") | G30: =+IFERROR(INDEX('Restaurant Base (Hidden)'!$A$2:$Z$1048576,MATCH($C30,'Restaurant Base (Hidden)'!$C$2:$C$1048576,0),MATCH(G$6,'Restaurant Base (Hidden)'!$A$1:$Z$1,0)),"") -> 4,677 | H30: =+IFERROR(INDEX('Restaurant Base (Hidden)'!$A$2:$Z$1048576,MATCH($C30,'Restaurant Base (Hidden)'!$C$2:$C$1048576,0),MATCH(H$6,'Restaurant Base (Hidden)'!$A$1:$Z$1,0)),"") -> 5 | I30: =+IFERROR(INDEX('Restaurant Base (Hidden)'!$A$2:$Z$1048576,MATCH($C30,'Restaurant Base (Hidden)'!$C$2:$C$1048576,0),MATCH(I$6,'Restaurant Base (Hidden)'!$A$1:$Z$1,0)),"") -> 94,40 % | J30: =+IFERROR(INDEX('Restaurant Base (Hidden)'!$A$2:$Z$1048576,MATCH($C30,'Restaurant Base (Hidden)'!$C$2:$C$1048576,0),MATCH(J$6,'Restaurant Base (Hidden)'!$A$1:$Z$1,0)),"") -> 5 | K30: =+IFERROR(INDEX('Restaurant Base (Hidden)'!$A$2:$Z$1048576,MATCH($C30,'Restaurant Base (Hidden)'!$C$2:$C$1048576,0),MATCH(K$6,'Restaurant Base (Hidden)'!$A$1:$Z$1,0)),"") -> 0,158 | L30: =+IFERROR(INDEX('Restaurant Base (Hidden)'!$A$2:$Z$1048576,MATCH($C30,'Restaurant Base (Hidden)'!$C$2:$C$1048576,0),MATCH(L$6,'Restaurant Base (Hidden)'!$A$1:$Z$1,0)),"") -> 2 | ... AG30: =+IFERROR(INDEX('Restaurant Base (Hidden)'!$A$2:$Z$1048576,MATCH($C30,'Restaurant Base (Hidden)'!$C$2:$C$1048576,0),MATCH(AG$6,'Restaurant Base (Hidden)'!$A$1:$Z$1,0)),"") -> 4
A31: =IF('Restaurant Base (Hidden)'!A224=0,"", 'Restaurant Base (Hidden)'!A224) -> Skyler Everhart | B31: =IF('Restaurant Base (Hidden)'!B224=0,"", 'Restaurant Base (Hidden)'!B224) -> Brookvale Dining | C31: =IF('Restaurant Base (Hidden)'!C224=0,"", 'Restaurant Base (Hidden)'!C224) -> Royal Harbor | D31: =+IFERROR(RANK(E31,$E$7:$E$3390,),"") -> 22 | E31: =+IFERROR(INDEX('Restaurant Base (Hidden)'!$A$2:$Z$1048576,MATCH($C31,'Restaurant Base (Hidden)'!$C$2:$C$1048576,0),MATCH(E$6,'Restaurant Base (Hidden)'!$A$1:$Z$1,0)),"") -> 3.72 | F31: =+IFERROR(INDEX('Restaurant Base (Hidden)'!$A$2:$Z$1048576,MATCH($C31,'Restaurant Base (Hidden)'!$C$2:$C$1048576,0),MATCH(F$6,'Restaurant Base (Hidden)'!$A$1:$Z$1,0)),"") | G31: =+IFERROR(INDEX('Restaurant Base (Hidden)'!$A$2:$Z$1048576,MATCH($C31,'Restaurant Base (Hidden)'!$C$2:$C$1048576,0),MATCH(G$6,'Restaurant Base (Hidden)'!$A$1:$Z$1,0)),"") -> 4,399 | H31: =+IFERROR(INDEX('Restaurant Base (Hidden)'!$A$2:$Z$1048576,MATCH($C31,'Restaurant Base (Hidden)'!$C$2:$C$1048576,0),MATCH(H$6,'Restaurant Base (Hidden)'!$A$1:$Z$1,0)),"") -> 4 | I31: =+IFERROR(INDEX('Restaurant Base (Hidden)'!$A$2:$Z$1048576,MATCH($C31,'Restaurant Base (Hidden)'!$C$2:$C$1048576,0),MATCH(I$6,'Restaurant Base (Hidden)'!$A$1:$Z$1,0)),"") -> 92,30 % | J31: =+IFERROR(INDEX('Restaurant Base (Hidden)'!$A$2:$Z$1048576,MATCH($C31,'Restaurant Base (Hidden)'!$C$2:$C$1048576,0),MATCH(J$6,'Restaurant Base (Hidden)'!$A$1:$Z$1,0)),"") -> 4 | K31: =+IFERROR(INDEX('Restaurant Base (Hidden)'!$A$2:$Z$1048576,MATCH($C31,'Restaurant Base (Hidden)'!$C$2:$C$1048576,0),MATCH(K$6,'Restaurant Base (Hidden)'!$A$1:$Z$1,0)),"") -> 0,083 | L31: =+IFERROR(INDEX('Restaurant Base (Hidden)'!$A$2:$Z$1048576,MATCH($C31,'Restaurant Base (Hidden)'!$C$2:$C$1048576,0),MATCH(L$6,'Restaurant Base (Hidden)'!$A$1:$Z$1,0)),"") -> 4 | ... AG31: =+IFERROR(INDEX('Restaurant Base (Hidden)'!$A$2:$Z$1048576,MATCH($C31,'Restaurant Base (Hidden)'!$C$2:$C$1048576,0),MATCH(AG$6,'Restaurant Base (Hidden)'!$A$1:$Z$1,0)),"") -> 3
A32: =IF('Restaurant Base (Hidden)'!A401=0,"", 'Restaurant Base (Hidden)'!A401) -> Emerson Greenleigh | B32: =IF('Restaurant Base (Hidden)'!B401=0,"", 'Restaurant Base (Hidden)'!B401) -> Sunridge Food Partners | C32: =IF('Restaurant Base (Hidden)'!C401=0,"", 'Restaurant Base (Hidden)'!C401) -> Fox Creek | D32: =+IFERROR(RANK(E32,$E$7:$E$3390,),"") -> 22 | E32: =+IFERROR(INDEX('Restaurant Base (Hidden)'!$A$2:$Z$1048576,MATCH($C32,'Restaurant Base (Hidden)'!$C$2:$C$1048576,0),MATCH(E$6,'Restaurant Base (Hidden)'!$A$1:$Z$1,0)),"") -> 3.72 | F32: =+IFERROR(INDEX('Restaurant Base (Hidden)'!$A$2:$Z$1048576,MATCH($C32,'Restaurant Base (Hidden)'!$C$2:$C$1048576,0),MATCH(F$6,'Restaurant Base (Hidden)'!$A$1:$Z$1,0)),"") | G32: =+IFERROR(INDEX('Restaurant Base (Hidden)'!$A$2:$Z$1048576,MATCH($C32,'Restaurant Base (Hidden)'!$C$2:$C$1048576,0),MATCH(G$6,'Restaurant Base (Hidden)'!$A$1:$Z$1,0)),"") -> 4,645 | H32: =+IFERROR(INDEX('Restaurant Base (Hidden)'!$A$2:$Z$1048576,MATCH($C32,'Restaurant Base (Hidden)'!$C$2:$C$1048576,0),MATCH(H$6,'Restaurant Base (Hidden)'!$A$1:$Z$1,0)),"") -> 5 | I32: =+IFERROR(INDEX('Restaurant Base (Hidden)'!$A$2:$Z$1048576,MATCH($C32,'Restaurant Base (Hidden)'!$C$2:$C$1048576,0),MATCH(I$6,'Restaurant Base (Hidden)'!$A$1:$Z$1,0)),"") -> 97,10 % | J32: =+IFERROR(INDEX('Restaurant Base (Hidden)'!$A$2:$Z$1048576,MATCH($C32,'Restaurant Base (Hidden)'!$C$2:$C$1048576,0),MATCH(J$6,'Restaurant Base (Hidden)'!$A$1:$Z$1,0)),"") -> 5 | K32: =+IFERROR(INDEX('Restaurant Base (Hidden)'!$A$2:$Z$1048576,MATCH($C32,'Restaurant Base (Hidden)'!$C$2:$C$1048576,0),MATCH(K$6,'Restaurant Base (Hidden)'!$A$1:$Z$1,0)),"") -> 0,162 | L32: =+IFERROR(INDEX('Restaurant Base (Hidden)'!$A$2:$Z$1048576,MATCH($C32,'Restaurant Base (Hidden)'!$C$2:$C$1048576,0),MATCH(L$6,'Restaurant Base (Hidden)'!$A$1:$Z$1,0)),"") -> 2 | ... AG32: =+IFERROR(INDEX('Restaurant Base (Hidden)'!$A$2:$Z$1048576,MATCH($C32,'Restaurant Base (Hidden)'!$C$2:$C$1048576,0),MATCH(AG$6,'Restaurant Base (Hidden)'!$A$1:$Z$1,0)),"") -> 3
A33: =IF('Restaurant Base (Hidden)'!A367=0,"", 'Restaurant Base (Hidden)'!A367) -> Riley Wellington | B33: =IF('Restaurant Base (Hidden)'!B367=0,"", 'Restaurant Base (Hidden)'!B367) -> Brightfield Dining | C33: =IF('Restaurant Base (Hidden)'!C367=0,"", 'Restaurant Base (Hidden)'!C367) -> Sunny House | D33: =+IFERROR(RANK(E33,$E$7:$E$3390,),"") -> 27 | E33: =+IFERROR(INDEX('Restaurant Base (Hidden)'!$A$2:$Z$1048576,MATCH($C33,'Restaurant Base (Hidden)'!$C$2:$C$1048576,0),MATCH(E$6,'Restaurant Base (Hidden)'!$A$1:$Z$1,0)),"") -> 3.71 | F33: =+IFERROR(INDEX('Restaurant Base (Hidden)'!$A$2:$Z$1048576,MATCH($C33,'Restaurant Base (Hidden)'!$C$2:$C$1048576,0),MATCH(F$6,'Restaurant Base (Hidden)'!$A$1:$Z$1,0)),"") | G33: =+IFERROR(INDEX('Restaurant Base (Hidden)'!$A$2:$Z$1048576,MATCH($C33,'Restaurant Base (Hidden)'!$C$2:$C$1048576,0),MATCH(G$6,'Restaurant Base (Hidden)'!$A$1:$Z$1,0)),"") -> 4,814 | H33: =+IFERROR(INDEX('Restaurant Base (Hidden)'!$A$2:$Z$1048576,MATCH($C33,'Restaurant Base (Hidden)'!$C$2:$C$1048576,0),MATCH(H$6,'Restaurant Base (Hidden)'!$A$1:$Z$1,0)),"") -> 5 | I33: =+IFERROR(INDEX('Restaurant Base (Hidden)'!$A$2:$Z$1048576,MATCH($C33,'Restaurant Base (Hidden)'!$C$2:$C$1048576,0),MATCH(I$6,'Restaurant Base (Hidden)'!$A$1:$Z$1,0)),"") -> 78,70 % | J33: =+IFERROR(INDEX('Restaurant Base (Hidden)'!$A$2:$Z$1048576,MATCH($C33,'Restaurant Base (Hidden)'!$C$2:$C$1048576,0),MATCH(J$6,'Restaurant Base (Hidden)'!$A$1:$Z$1,0)),"") -> 2 | K33: =+IFERROR(INDEX('Restaurant Base (Hidden)'!$A$2:$Z$1048576,MATCH($C33,'Restaurant Base (Hidden)'!$C$2:$C$1048576,0),MATCH(K$6,'Restaurant Base (Hidden)'!$A$1:$Z$1,0)),"") -> 0,037 | L33: =+IFERROR(INDEX('Restaurant Base (Hidden)'!$A$2:$Z$1048576,MATCH($C33,'Restaurant Base (Hidden)'!$C$2:$C$1048576,0),MATCH(L$6,'Restaurant Base (Hidden)'!$A$1:$Z$1,0)),"") -> 5 | ... AG33: =+IFERROR(INDEX('Restaurant Base (Hidden)'!$A$2:$Z$1048576,MATCH($C33,'Restaurant Base (Hidden)'!$C$2:$C$1048576,0),MATCH(AG$6,'Restaurant Base (Hidden)'!$A$1:$Z$1,0)),"") -> 1
